<?xml version="1.0"?>
<robot name="urdfbot">

<link name="Torso_Pelvis_Block_Part">
    <visual>
    <origin rpy="0 0 0" xyz="0 0 0" />
        <geometry>
            <mesh filename="package://robot_description/meshes/robot/Torso_Pelvis_Block_Part.STL"/>
        </geometry>
        <material
        name="">
        <color
          rgba="0.79216 0.81961 0.93333 1" />
      </material>
    </visual>
</link>
<link name="HipRollR_Part">
    <visual>
    <origin rpy="0 0 0" xyz="0 0 0" />
    <geometry>
        <mesh filename="package://robot_description/meshes/robot/HipRollR_Part.STL"/>
    </geometry>
    <material
        name="">
        <color
          rgba="0.792156862745098 0.819607843137255 0.933333333333333 1" />
      </material>
    </visual>
</link>
<joint name="HipYaw_R" type="revolute">
    <origin xyz="0 -0.13 -0.046446" rpy="0 0 0"/>
    <parent link="Torso_Pelvis_Block_Part"/>
    <child link="HipRollR_Part"/>
    <axis xyz="0 0 -1"/>
    <limit effort="351" velocity="8.3775" lower="-0.4363" upper="0.4363"/>
</joint>

<link
    name="HipPitchR_Part">
    <visual>
      <origin
        xyz="0 0 0"
        rpy="0 0 0" />
      <geometry>
        <mesh
          filename="package://robot_description/meshes/robot/HipPitchR_Part.STL" />
      </geometry>
       <material
        name="">
        <color
          rgba="0.792156862745098 0.819607843137255 0.933333333333333 1" />
      </material>
    </visual>
  </link>
  <joint name="HipRoll_R" type="revolute">
    <origin xyz="0 0.00065 -0.086"
            rpy="0 0 0" />
    <parent link="HipRollR_Part" />
    <child link="HipPitchR_Part" />
    <axis xyz="1 0 0" />
    <limit
      lower="-0.8727"
      upper="0.3927"
      effort="351"
      velocity="8.3775" />
  </joint>

<link
    name="ThighR_Part">
    <visual>
      <origin
        xyz="0 0 0"
        rpy="0 0 0" />
      <geometry>
        <mesh
          filename="package://robot_description/meshes/robot/ThighR_Part.STL" />
      </geometry>
      <material
        name="">
        <color
          rgba="0.792156862745098 0.819607843137255 0.933333333333333 1" />
      </material>
    </visual>
    
  </link>
  <joint
    name="HipPitch_R"
    type="revolute">
    <origin
      xyz="0 0 0"
      rpy="0 0 0" />
    <parent
      link="HipPitchR_Part" />
    <child
      link="ThighR_Part" />
    <axis
      xyz="0 1 0" />
    <limit
      lower="-1.92"
      upper="0.7854"
      effort="298"
      velocity="16.775" />
  </joint>

  <link
    name="ShankR_Part">
   
    <visual>
      <origin
        xyz="0 0 0"
        rpy="0 0 0" />
      <geometry>
        <mesh
          filename="package://robot_description/meshes/robot/ShankR_Part.STL" />
      </geometry>
      <material
        name="">
        <color
          rgba="0.792156862745098 0.819607843137255 0.933333333333333 1" />
      </material>
    </visual>
  </link>

  <joint
    name="KneePitch_R"
    type="revolute">
    <origin
      xyz="0 0 -0.44"
      rpy="0 0 0" />
    <parent
      link="ThighR_Part" />
    <child
      link="ShankR_Part" />
    <axis
      xyz="0 1 0" />
    <limit
      lower="-0.087"
      upper="2.1817"
      effort="420.6"
      velocity="6.9813" />
  
  </joint>
  <link
    name="AnkleRollR_Part">
    <visual>
      <origin
        xyz="0 0 0"
        rpy="0 0 0" />
      <geometry>
        <mesh
          filename="package://robot_description/meshes/robot/AnkleRollR_Part.STL" />
      </geometry>
      <material
        name="">
        <color
          rgba="0.792156862745098 0.819607843137255 0.933333333333333 1" />
      </material>
    </visual>
  </link>
  <joint
    name="AnkleRoll_R"
    type="revolute">
    <origin
      xyz="0 0 -0.43"
      rpy="0 0 0" />
    <parent
      link="ShankR_Part" />
    <child
      link="AnkleRollR_Part" />
    <axis
      xyz="-1 0 0" />
    <limit
      lower="-0.6109"
      upper="0.6109"
      effort="131.4"
      velocity="3.4906" />
  </joint>

  <link
    name="AnklePitch_Part">
   
    <visual>
      <origin
        xyz="0 0 0"
        rpy="0 0 0" />
      <geometry>
        <mesh
          filename="package://robot_description/meshes/robot/AnklePitch_Part.STL" />
      </geometry>
      <material
        name="">
        <color
          rgba="0.792156862745098 0.819607843137255 0.933333333333333 1" />
      </material>
    </visual>
   
  </link>
  <joint
    name="AnklePitch_R"
    type="revolute">
    <origin
      xyz="0 0 0"
      rpy="0 0 0" />
    <parent
      link="AnkleRollR_Part" />
    <child
      link="AnklePitch_Part" />
    <axis
      xyz="0 1 0" />
    <limit
      lower="-1.0821"
      upper="0.7854"
      effort="262.8"
      velocity="6.9813" />
   
  </joint>
  <link
    name="HipRollL_Part">
    
    <visual>
      <origin
        xyz="0 0 0"
        rpy="0 0 0" />
      <geometry>
        <mesh
          filename="package://robot_description/meshes/robot/HipRollL_Part.STL" />
      </geometry>
      <material
        name="">
        <color
          rgba="0.792156862745098 0.819607843137255 0.933333333333333 1" />
      </material>
    </visual>
   
  </link>
  <joint
    name="HipYaw_L"
    type="revolute">
    <origin
      xyz="0 0.078 -0.046446"
      rpy="0 0 0" />
    <parent
      link="Torso_Pelvis_Block_Part" />
    <child
      link="HipRollL_Part" />
    <axis
      xyz="0 0 -1" />
    <limit
      lower="-0.4363"
      upper="0.4363"
      effort="351"
      velocity="8.3775" />
   
  </joint>
  <link
    name="HipPitchL_Part">
   
    <visual>
      <origin
        xyz="0 0 0"
        rpy="0 0 0" />
      <geometry>
        <mesh
          filename="package://robot_description/meshes/robot/HipPitchL_Part.STL" />
      </geometry>
      <material
        name="">
        <color
          rgba="0.792156862745098 0.819607843137255 0.933333333333333 1" />
      </material>
    </visual>
    
  </link>
  <joint
    name="HipRoll_L"
    type="revolute">
    <origin
      xyz="0 0.05135 -0.086"
      rpy="0 0 0" />
    <parent
      link="HipRollL_Part" />
    <child
      link="HipPitchL_Part" />
    <axis
      xyz="1 0 0" />
    <limit
      lower="-0.3927"
      upper="0.8727"
      effort="351"
      velocity="8.3775" />
  </joint>
  <link
    name="ThighPartL_Part">
   
    <visual>
      <origin
        xyz="0 0 0"
        rpy="0 0 0" />
      <geometry>
        <mesh
          filename="package://robot_description/meshes/robot/ThighPartL_Part.STL" />
      </geometry>
      <material
        name="">
        <color
          rgba="0.792156862745098 0.819607843137255 0.933333333333333 1" />
      </material>
    </visual>
    
  </link>
  <joint
    name="HipPitch_L"
    type="revolute">
    <origin
      xyz="0 0 0"
      rpy="0 0 0" />
    <parent
      link="HipPitchL_Part" />
    <child
      link="ThighPartL_Part" />
    <axis
      xyz="0 1 0" />
    <limit
      lower="-0.7854"
      upper="1.92"
      effort="298"
      velocity="16.775" />
   
  </joint>
  <link
    name="ShankL_Part">
    
    <visual>
      <origin
        xyz="0 0 0"
        rpy="0 0 0" />
      <geometry>
        <mesh
          filename="package://robot_description/meshes/robot/ShankL_Part.STL" />
      </geometry>
      <material
        name="">
        <color
          rgba="0.792156862745098 0.819607843137255 0.933333333333333 1" />
      </material>
    </visual>
   
  </link>
  <joint
    name="KneePitch_L"
    type="revolute">
    <origin
      xyz="0 0 -0.44"
      rpy="0 0 0" />
    <parent
      link="ThighPartL_Part" />
    <child
      link="ShankL_Part" />
    <axis
      xyz="0 1 0" />
    <limit
      lower="-0.087"
      upper="2.1817"
      effort="420.6"
      velocity="6.9813" />
   
  </joint>
  <link
    name="AnkleRollL_Part">
    
    <visual>
      <origin
        xyz="0 0 0"
        rpy="0 0 0" />
      <geometry>
        <mesh
          filename="package://robot_description/meshes/robot/AnkleRollL_Part.STL" />
      </geometry>
      <material
        name="">
        <color
          rgba="0.792156862745098 0.819607843137255 0.933333333333333 1" />
      </material>
    </visual>
   
  </link>
  <joint
    name="AnkleRoll_L"
    type="revolute">
    <origin
      xyz="0 0 -0.43"
      rpy="0 0 0" />
    <parent
      link="ShankL_Part" />
    <child
      link="AnkleRollL_Part" />
    <axis
      xyz="-1 0 0" />
    <limit
      lower="-0.6109"
      upper="0.6109"
      effort="131.4"
      velocity="3.4906" />
   
  </joint>
  <link
    name="AnklePitchL_Part">
   
    <visual>
      <origin
        xyz="0 0 0"
        rpy="0 0 0" />
      <geometry>
        <mesh
          filename="package://robot_description/meshes/robot/AnklePitchL_Part.STL" />
      </geometry>
      <material
        name="">
        <color
          rgba="0.792156862745098 0.819607843137255 0.933333333333333 1" />
      </material>
    </visual>
    
  </link>
  <joint
    name="AnklePitch_L"
    type="revolute">
    <origin
      xyz="0 0 0"
      rpy="0 0 0" />
    <parent
      link="AnkleRollL_Part" />
    <child
      link="AnklePitchL_Part" />
    <axis
      xyz="0 1 0" />
    <limit
      lower="-0.7854"
      upper="1.0821"
      effort="262.8"
      velocity="6.9813" />
   
  </joint>
  <link
    name="Pelvis_Roll_Part">
   
    <visual>
      <origin
        xyz="0 0 0"
        rpy="0 0 0" />
      <geometry>
        <mesh
          filename="package://robot_description/meshes/robot/Pelvis_Roll_Part.STL" />
      </geometry>
      <material
        name="">
        <color
          rgba="0.79216 0.81961 0.93333 1" />
      </material>
    </visual>
    
  </link>
  <joint
    name="Pelvis_Roll"
    type="revolute">
    <origin
      xyz="0 0 0.030054"
      rpy="0 0 0" />
    <parent
      link="Torso_Pelvis_Block_Part" />
    <child
      link="Pelvis_Roll_Part" />
    <axis
      xyz="-1 0 0" />
    <limit
      lower="-0.3491"
      upper="0.3491"
      effort="130"
      velocity="8.3775" />
   
  </joint>
  <link
    name="Torso">
   
    <visual>
      <origin
        xyz="0 0 0"
        rpy="0 0 0" />
      <geometry>
        <mesh
          filename="package://robot_description/meshes/robot/Torso.STL" />
      </geometry>
      <material
        name="">
        <color
          rgba="0.79216 0.81961 0.93333 1" />
      </material>
    </visual>
   
  </link>
  <joint
    name="Pelvis_Yaw"
    type="revolute">
    <origin
      xyz="-0.1335 0 0"
      rpy="0 0 0" />
    <parent
      link="Pelvis_Roll_Part" />
    <child
      link="Torso" />
    <axis
      xyz="0 0 1" />
    <limit
      lower="-0.3491"
      upper="0.3491"
      effort="130"
      velocity="8.3775" />
  
  </joint>

</robot>