<?xml version="1.0"?>
<robot name="cube">

<material name="blue">
    <color rgba="0.006 0.151 0.581 1"/>
</material>
<material name="white"> 
    <color rgba="1.0 0.91 0.827 1"/>
</material> 

<link name="base_link"></link>

<link name="link1">
    <visual>
    <origin rpy="0 0 0" xyz="0 0 0" />
        <geometry>
            <box size="0.1 0.1 0.1"/>
        </geometry>
        <material name="white"/>
    </visual>
    <inertial>
      <origin
        xyz="0 0 0"
        rpy="0 0 0" />
      <mass
        value="7.20094" />
      <inertia
        ixx="0.110444382"
        ixy="1.41826E-06"
        ixz="-0.000301506"
        iyy="0.024224628"
        iyz="-3.1726E-06"
        izz="0.108900947" />
    </inertial>
    <collision>
      <origin
        xyz="0 0 0"
        rpy="0 0 0" />
      <geometry>
        <box size="0.1 0.1 0.1"/>
      </geometry>
    </collision> 
</link>
 <joint name="joint_base_link_link1" type="fixed">
        <origin rpy="0 0 0" xyz="0 0 0" />
        <child link="link1" />
        <parent link="base_link" />
        <joint_properties damping="1.0" friction="1.0" />
    </joint>

<link name="head_link">
    <visual>
        <origin rpy="0 0 0" xyz="0 0 0.1" /> <!-- ORIGIN DISPLACEMENT ADDED -->
        <geometry>
            <box size="0.1 0.1 0.1"/>
        </geometry>
        <material name="blue"/>
    </visual>
    <inertial>
      <origin
        xyz="-0.0041 -1E-05 0.02016"
        rpy="0 0 0" />
      <mass 
        value="7.20094" />
      <inertia
        ixx="0.110444382"
        ixy="1.41826E-06"
        ixz="-0.000301506"
        iyy="0.024224628"
        iyz="-3.1726E-06"
        izz="0.108900947" />
    </inertial>
    <collision>
      <origin
        xyz="0 0 0"
        rpy="0 0 0" />
      <geometry>
        <box size="0.1 0.1 0.1"/>
      </geometry>
    </collision>
</link>

<joint name="base_link_to_head_link_joint" type="revolute">
    <origin rpy="0 0 0" xyz="0 0 0.11" />
    <parent link="link1" />
    <child link="head_link" />
    <axis xyz="0 0 1"/>
    <limit effort="100" velocity="1.0" lower="-1.57" upper="1.57"/>
</joint>
</robot>
